<mujoco>   
    <body name="right_gripper_base" pos="0 0 0.025">
    <inertial pos="0 0 0" quat="-0.5 0.5 0.5 0.5" mass="0.3" diaginertia="3e-08 2e-08 2e-08" />
    <geom quat="0 0 0.707107 0.707107" class="viz" mesh="electric_gripper_base" />
    <geom size="0.029 0.05" quat="0 0 0.707107 0.707107" type="cylinder" />
    <body name="r_gripper_l_finger" pos="0 -0.0015 0.02">
        <inertial pos="0 0 0" quat="0 0 0 -1" mass="0.02" diaginertia="0.01 0.01 0.01" />
        <joint name="r_gripper_l_finger_joint" pos="0 0 0" axis="0 1 0" type="slide" range="0.02 0.045" armature="100" damping="1000" limited="true" solimplimit="0.99 0.999 0.01" solreflimit="0.01 1"/>
        <geom class="viz" mesh="finger_extended_narrow" euler="1.57 1.57 0" rgba="0.1 0.1 0.1 1"/>
        <geom size="0.005 0.00675 0.05635" contype="0" pos="0 0.01725 0.0615" quat="0 0 0 -1" type="box" rgba="0.1 0.1 0.1 1"/>
        <geom size="0.005 0.025 0.0085" contype="0" pos="-0.005 -0.003 0.0083" quat="0 0 0 -1" type="box" rgba="0.1 0.1 0.1 1"/>
        <body name="r_gripper_l_finger_tip" pos="0 0.01725 0.1127">
            <inertial pos="0 0 0" quat="0 0 0 1" mass="0.01" diaginertia="0.01 0.01 0.01" />
            <geom pos="-.007 -.01 0.003" class="viz" mesh="half_round_tip" euler="-1.57 0 0" friction="0 0 0"/>
            <geom name="finger_tip_1" size="0.008 0.008 0.0185" pos="0 -0.0045 -0.015" quat="0 0 0 1" type="box" friction="0 0 0"/>
        </body>
    </body>
    <body name="r_gripper_r_finger" pos="0 0.0015 0.02">
        <inertial pos="0 0 0" mass="0.02" diaginertia="0.01 0.01 0.01" />
        <joint name="r_gripper_r_finger_joint" pos="0 0 0" axis="0 1 0" type="slide" range="-0.045 -0.02" armature="100" damping="1000" limited="true" solimplimit="0.99 0.999 0.01" solreflimit="0.01 1"/>
        <geom class="viz" mesh="finger_extended_narrow" euler="1.57 -1.57 0" rgba="0.1 0.1 0.1 1"/>
        <geom size="0.005 0.00675 0.05635" contype="0" pos="0 -0.01725 0.0615" type="box" rgba="0.1 0.1 0.1 1"/>
        <geom size="0.005 0.025 0.0085" contype="0" pos="0.005 0.003 0.0083" type="box" rgba="0.1 0.1 0.1 1"/>
        <body name="r_gripper_r_finger_tip" pos="0 -0.01725 0.1127">
            <inertial pos="0 0 0" mass="0.01" diaginertia="0.01 0.01 0.01" />
            <geom pos=".007 .01 0.003" class="viz" mesh="half_round_tip" euler="-1.57 3.14 0" friction="0 0 0"/>
            <geom name="finger_tip_2" size="0.008 0.008 0.0185" pos="0 0.0045 -0.015" type="box" friction="0 0 0"/>
        </body>
    </body>
    <site name="gripper_site" pos="0 0 0.135" rgba="0 0 0 1" size="0.01" type="sphere"></site>
    </body>
</mujoco>